[2024-07-05T10:47:47.339+0000] {taskinstance.py:1165} INFO - Dependencies all met for <TaskInstance: producer.update_dataset scheduled__2024-07-04T00:00:00+00:00 [queued]>
[2024-07-05T10:47:47.349+0000] {taskinstance.py:1165} INFO - Dependencies all met for <TaskInstance: producer.update_dataset scheduled__2024-07-04T00:00:00+00:00 [queued]>
[2024-07-05T10:47:47.349+0000] {taskinstance.py:1362} INFO - 
--------------------------------------------------------------------------------
[2024-07-05T10:47:47.350+0000] {taskinstance.py:1363} INFO - Starting attempt 4 of 4
[2024-07-05T10:47:47.350+0000] {taskinstance.py:1364} INFO - 
--------------------------------------------------------------------------------
[2024-07-05T10:47:47.376+0000] {taskinstance.py:1383} INFO - Executing <Task(_PythonDecoratedOperator): update_dataset> on 2024-07-04 00:00:00+00:00
[2024-07-05T10:47:47.384+0000] {standard_task_runner.py:55} INFO - Started process 86345 to run task
[2024-07-05T10:47:47.390+0000] {standard_task_runner.py:82} INFO - Running: ['***', 'tasks', 'run', 'producer', 'update_dataset', 'scheduled__2024-07-04T00:00:00+00:00', '--job-id', '82', '--raw', '--subdir', 'DAGS_FOLDER/producer.py', '--cfg-path', '/tmp/tmp5yo2x13_']
[2024-07-05T10:47:47.392+0000] {standard_task_runner.py:83} INFO - Job 82: Subtask update_dataset
[2024-07-05T10:47:47.478+0000] {task_command.py:376} INFO - Running <TaskInstance: producer.update_dataset scheduled__2024-07-04T00:00:00+00:00 [running]> on host 409ff340d891
[2024-07-05T10:47:47.546+0000] {taskinstance.py:1592} INFO - Exporting the following env vars:
AIRFLOW_CTX_DAG_OWNER=***
AIRFLOW_CTX_DAG_ID=producer
AIRFLOW_CTX_TASK_ID=update_dataset
AIRFLOW_CTX_EXECUTION_DATE=2024-07-04T00:00:00+00:00
AIRFLOW_CTX_TRY_NUMBER=4
AIRFLOW_CTX_DAG_RUN_ID=scheduled__2024-07-04T00:00:00+00:00
[2024-07-05T10:47:47.547+0000] {taskinstance.py:1851} ERROR - Task failed with exception
Traceback (most recent call last):
  File "/home/airflow/.local/lib/python3.7/site-packages/airflow/decorators/base.py", line 188, in execute
    return_value = super().execute(context)
  File "/home/airflow/.local/lib/python3.7/site-packages/airflow/operators/python.py", line 175, in execute
    return_value = self.execute_callable()
  File "/home/airflow/.local/lib/python3.7/site-packages/airflow/operators/python.py", line 193, in execute_callable
    return self.python_callable(*self.op_args, **self.op_kwargs)
  File "/opt/airflow/dags/producer.py", line 17, in update_dataset
    with open(my_file.uri, "a+") as f:
FileNotFoundError: [Errno 2] No such file or directory: '/temp/my_file.text'
[2024-07-05T10:47:47.555+0000] {taskinstance.py:1406} INFO - Marking task as FAILED. dag_id=producer, task_id=update_dataset, execution_date=20240704T000000, start_date=20240705T104747, end_date=20240705T104747
[2024-07-05T10:47:47.564+0000] {standard_task_runner.py:105} ERROR - Failed to execute job 82 for task update_dataset ([Errno 2] No such file or directory: '/temp/my_file.text'; 86345)
[2024-07-05T10:47:47.603+0000] {local_task_job.py:164} INFO - Task exited with return code 1
[2024-07-05T10:47:47.620+0000] {local_task_job.py:273} INFO - 0 downstream tasks scheduled from follow-on schedule check
